<?xml version="1.0" ?>
<robot name="xArm">

  <link name="world"/>

  <joint name="world_joint" type="fixed">
    <parent link="world"/>
    <child link="base_link"/>
    <origin rpy="0.0 0.0 0.0" xyz="0.0 0.0 0.05"/>
  </joint>

  <link name="base_link"/>

  <joint name="arm1" type="continuous">
    <parent link="base_link"/>
    <child link="link1"/>
    <origin rpy="0.0 0.0 0.0" xyz="0.0 0.0 0.05"/>
    <axis xyz="0 0 1"/>
  </joint>

  <link name="link1">
    <visual>
      <origin rpy="0 0 0.0" xyz="0 0 0.0065"/>
      <geometry>
        <cylinder length="0.013" radius="0.04"/>
      </geometry>
      <material name="blue">
	<color rgba="0.3 0.5 0.9 1.0"/>
      </material>
    </visual>
    <visual>
      <origin rpy="0 0 0" xyz="0.011 0.0 0.01625"/>
      <geometry>
        <box size="0.044 0.0285 0.0065"/>
      </geometry>
      <material name="blue">
	<color rgba="0.3 0.5 0.9 1.0"/>
      </material>
    </visual>
    <visual>
      <origin rpy="0 0 0" xyz="0.011 0.0 0.031"/>
      <geometry>
        <box size="0.044 0.0285 0.023"/>
      </geometry>
      <material name="black">
	<color rgba="0.2 0.2 0.2 1"/>
      </material>
    </visual>
  </link>

  <joint name="arm2" type="continuous">
    <parent link="link1"/>
    <child link="link2"/>
    <origin rpy="0.0 0.0 0.0" xyz="0.0 0.0 0.0425"/>
    <axis xyz="0 1 0"/>
  </joint>

  <link name="link2">
    <visual>
      <origin rpy="0 0 0" xyz="0.0 0.02 0.0135"/>
      <geometry>
        <box size="0.032 0.002 0.052"/>
      </geometry>
      <material name="blue">
	<color rgba="0.3 0.5 0.9 1.0"/>
      </material>
    </visual>
    <visual>
      <origin rpy="0 0 0" xyz="0.0 -0.02 0.0135"/>
      <geometry>
        <box size="0.032 0.002 0.052"/>
      </geometry>
      <material name="blue">
	<color rgba="0.3 0.5 0.9 1.0"/>
      </material>
    </visual>
    <visual>
      <origin rpy="0 0 0" xyz="0.0 0.0 0.0385"/>
      <geometry>
        <box size="0.032 0.042 0.002"/>
      </geometry>
      <material name="blue">
	<color rgba="0.3 0.5 0.9 1.0"/>
      </material>
    </visual>
    <visual>
      <origin rpy="0 0 1.57075" xyz="0 0 0.054"/>
      <geometry>
        <cylinder length="0.029" radius="0.012"/>
      </geometry>
      <material name="white">
	<color rgba="0.9 0.9 0.9 1.0"/>
      </material>
    </visual>
    <visual>
      <origin rpy="0 0 0" xyz="0.0 0.0 0.0695"/>
      <geometry>
        <box size="0.025 0.042 0.002"/>
      </geometry>
      <material name="blue">
	<color rgba="0.3 0.5 0.9 1.0"/>
      </material>
    </visual>
    <visual>
      <origin rpy="0 0 0" xyz="0.0 0.02 0.091"/>
      <geometry>
        <box size="0.025 0.002 0.045"/>
      </geometry>
      <material name="blue">
	<color rgba="0.3 0.5 0.9 1.0"/>
      </material>
    </visual>
    <visual>
      <origin rpy="0 0 0" xyz="0.0 -0.02 0.091"/>
      <geometry>
        <box size="0.025 0.002 0.045"/>
      </geometry>
      <material name="blue">
	<color rgba="0.3 0.5 0.9 1.0"/>
      </material>
    </visual>
  </link>

  <joint name="arm3" type="continuous">
    <parent link="link2"/>
    <child link="link3"/>
    <origin rpy="0.0 0.0 0.0" xyz="0.0 0.0 0.0965"/>
    <axis xyz="0 1 0"/>
  </joint>

  <link name="link3">
    <visual>
      <origin rpy="0 0 0" xyz="0.0 0.0 0.011"/>
      <geometry>
        <box size="0.023 0.0285 0.044"/>
      </geometry>
      <material name="black">
	<color rgba="0.2 0.2 0.2 1"/>
      </material>
    </visual>
    <visual>
      <origin rpy="0 0 0" xyz="0.0 0.0 0.035"/>
      <geometry>
        <box size="0.023 0.0285 0.004"/>
      </geometry>
      <material name="blue">
	<color rgba="0.3 0.5 0.9 1.0"/>
      </material>
    </visual>
    <visual>
      <origin rpy="0 0 1.57075" xyz="0 0 0.0475"/>
      <geometry>
        <cylinder length="0.021" radius="0.0105"/>
      </geometry>
      <material name="white">
	<color rgba="0.9 0.9 0.9 1.0"/>
      </material>
    </visual>
    <visual>
      <origin rpy="0 0 0" xyz="0.0 0.0 0.060"/>
      <geometry>
        <box size="0.023 0.0285 0.004"/>
      </geometry>
      <material name="blue">
	<color rgba="0.3 0.5 0.9 1.0"/>
      </material>
    </visual>
    <visual>
      <origin rpy="0 0 0" xyz="0.0 0.0 0.084"/>
      <geometry>
        <box size="0.023 0.0285 0.044"/>
      </geometry>
      <material name="black">
	<color rgba="0.2 0.2 0.2 1"/>
      </material>
    </visual>
  </link>

  <joint name="arm4" type="continuous">
    <parent link="link3"/>
    <child link="link4"/>
    <origin rpy="0.0 0.0 0.0" xyz="0.0 0.0 0.0965"/>
    <axis xyz="0 1 0"/>
  </joint>

  <link name="link4">
    <visual>
      <origin rpy="0 0 0" xyz="0.0 0.02 0.0195"/>
      <geometry>
        <box size="0.025 0.002 0.064"/>
      </geometry>
      <material name="blue">
	<color rgba="0.3 0.5 0.9 1.0"/>
      </material>
    </visual>
    <visual>
      <origin rpy="0 0 0" xyz="0.0 -0.02 0.0195"/>
      <geometry>
        <box size="0.025 0.002 0.064"/>
      </geometry>
      <material name="blue">
	<color rgba="0.3 0.5 0.9 1.0"/>
      </material>
    </visual>
    <visual>
      <origin rpy="0 0 0" xyz="0.0 0.0 0.0505"/>
      <geometry>
        <box size="0.025 0.042 0.002"/>
      </geometry>
      <material name="blue">
	<color rgba="0.3 0.5 0.9 1.0"/>
      </material>
    </visual>
    <visual>
      <origin rpy="0 0 0" xyz="-0.011 0.0 0.03525"/>
      <geometry>
        <box size="0.044 0.023 0.0285"/>
      </geometry>
      <material name="black">
	<color rgba="0.2 0.2 0.2 1"/>
      </material>
    </visual>
  </link>

  <joint name="arm5" type="continuous">
    <parent link="link4"/>
    <child link="link5"/>
    <origin rpy="0.0 0.0 0.0" xyz="0.0 0.0 0.055"/>
    <axis xyz="0 0 1"/>
  </joint>

  <link name="link5">
    <visual>
      <origin rpy="0 0 0.0" xyz="0 0 0"/>
      <geometry>
        <cylinder length="0.004" radius="0.01"/>
      </geometry>
      <material name="black">
	<color rgba="0.2 0.2 0.2 1.0"/>
      </material>
    </visual>
  </link>
</robot>
